**Manejo de errores con try-catch en Node.js**

## Introducción

El manejo de errores es una parte fundamental en la programación, ya que nos permite controlar y reaccionar adecuadamente cuando ocurren situaciones inesperadas. En Node.js, uno de los enfoques para manejar errores es mediante el uso de bloques `try-catch`, que nos permiten capturar excepciones y tomar acciones en consecuencia.

En este README, exploraremos diferentes casos donde el uso de `try-catch` es útil para manejar errores en Node.js.

## Caso 1: Manejo de errores en funciones asíncronas

En escenarios donde trabajamos con funciones asíncronas que devuelven promesas, es recomendable utilizar `try-catch` para capturar y manejar posibles errores que puedan ocurrir durante la ejecución.

```javascript
// Ejemplo de función asíncrona con try-catch
async function fetchDataFromAPI() {
  try {
    const response = await fetch("https://api.example.com/data");
    const data = await response.json();
    console.log("Datos obtenidos:", data);
  } catch (error) {
    console.error("Error al obtener datos:", error.message);
  }
}
```

## Caso 2: Manejo de errores en funciones síncronas

En funciones síncronas, también podemos usar `try-catch` para capturar errores que puedan surgir y manejarlos de manera adecuada.

```javascript
// Ejemplo de función síncrona con try-catch
function divideNumbers(a, b) {
  try {
    if (b === 0) {
      throw new Error("División por cero no está permitida.");
    }
    const result = a / b;
    console.log("Resultado:", result);
  } catch (error) {
    console.error("Error al dividir:", error.message);
  }
}
```

## Caso 3: Encadenamiento de operaciones asincrónicas con try-catch

Cuando encadenamos varias operaciones asincrónicas, es importante recordar que cada una de ellas puede arrojar errores. En este caso, podemos usar `try-catch` para manejarlos y evitar que se propague el error a niveles superiores.

```javascript
// Ejemplo de encadenamiento de operaciones asincrónicas con try-catch
async function processTasks() {
  try {
    const data1 = await fetchDataFromAPI("task1");
    const data2 = await fetchDataFromAPI("task2");
    const result = await processData(data1, data2);
    console.log("Resultado final:", result);
  } catch (error) {
    console.error("Error al procesar tareas:", error.message);
  }
}
```

## Caso 4: Uso de try-catch en bloques anidados

En algunas ocasiones, podemos encontrarnos con bloques anidados de `try-catch`, especialmente cuando trabajamos con múltiples operaciones o flujos de control.

```javascript
// Ejemplo de try-catch en bloques anidados
function complexOperation() {
  try {
    // Algo que puede arrojar un error
  } catch (error) {
    console.error("Error en la operación principal:", error.message);
    try {
      // Algo más que puede arrojar un error
    } catch (nestedError) {
      console.error("Error en la operación anidada:", nestedError.message);
    }
  }
}
```

## Conclusión

El uso adecuado de `try-catch` en Node.js nos permite capturar y manejar errores de manera efectiva, lo que mejora la robustez y la fiabilidad de nuestras aplicaciones. Cada vez que se realice una operación que pueda generar un error, es recomendable considerar el uso de `try-catch` para garantizar un manejo adecuado de las excepciones y evitar la interrupción inesperada del programa.
